Error: failed external call: free_permission_context
After 0.966001s
SE started at depth/instruction 0
Current depth 0
Current instructions 719565
Current searcherdistance 0
Current TTL 0
Stack: 
	#0 00018965 in qset_acl (name=77675232, desc=4, mode=420)
	#1 00012305 in set_acl (name=77675232, desc=4, mode=420)
	#2 00006939 in copy_reg (src_name=60399408, dst_name=77675232, x=76414464, dst_mode, omitted_permissions=0, new_dst=80924288, src_sb=78837488)
	#3 00010112 in copy_internal (src_name=60399408, dst_name=77675232, new_dst=1, parent=0, ancestors=0, x=76414464, command_line_arg=1, first_dir_created_per_command_line_arg=76559616, copy_into_self=76649104, rename_succeeded=0)
	#4 00011224 in copy (src_name=60399408, dst_name=77675232, nonexistent_dst=1, options=76414464, copy_into_self=76649104, rename_succeeded=0)
	#5 00002163 in do_copy (n_files=2, file=76469368, target_directory=0, no_target_directory=0, x=76414464)
	#6 00003266 in __user_main (argc=5, argv=57370784)
	#7 00035271 in __uClibc_main (main=47028448, argc=5, argv=57370784, app_init=0, app_fini=0, rtld_fini=0, stack_end=0) at /home/shadowvm/shadow/kleeDeploy/klee-uclibc/libc/misc/internals/__uClibc_main.c:401
	#8 00052008 in main (=5, =57370784)
